Workbook

Sheet COAHUILA2010
A1: Población total | M1: Coahuila: nacimientos por grupos quinquenales de edad de la madre, 2010
A2: Entidad y municipio : Coahuila de Zaragoza
M4: Edad | N4: Coahuila 2010 | O4: Población 27/03/2010 | Q4: Coahuila: nacimientos por sexo, 2010
A5: Edad | B5: Coahuila 2000 | F5: Edad | G5: Coahuila 2010 | M5: 15-19 | N5: 11909 | O5: =S18 -> 129145.33
B6: Hombre | C6: Mujer | D6: Total | G6: Hombre | H6: Mujer | I6: Total | M6: 20-24 | N6: 16286 | O6: =S24 -> 114661.74 | Q6: Hombre | R6: Mujer | S6: Total
A7: 0-4 | B7: 129130 | C7: 124041 | D7: =SUM(B7,C7) -> 253171 | F7: 0-4 | G7: 131289 | H7: 126957 | I7: =SUM(G7:H7) -> 258246 | M7: 25-29 | N7: 13908 | O7: =S30 -> 105990.38 | Q7: 28879 | R7: 28093 | S7: 56972
A8: 5-9 | B8: 130718 | C8: 126510 | D8: =SUM(B8,C8) -> 257228 | F8: 5-9 | G8: 137858 | H8: 132878 | I8: =SUM(G8:H8) -> 270736 | M8: 30-34 | N8: 9223 | O8: =S36 -> 109920.41 | Q8: FUENTE: INEGI. Estadísticas de natalidad.
A9: 10-14 | B9: 119135 | C9: 115524 | D9: =SUM(B9,C9) -> 234659 | F9: 10-14 | G9: 136153 | H9: 132040 | I9: =SUM(G9:H9) -> 268193 | M9: 35-39 | N9: 3795 | O9: =S42 -> 107873.41
A10: 15-19 | B10: 113776 | C10: 111640 | D10: =SUM(B10,C10) -> 225416 | F10: 15-19 | G10: 132477 | H10: 129465 | I10: =SUM(G10:H10) -> 261942 | M10: 40-44 | N10: 725 | O10: =S48 -> 90686.224 | Q10: K | R10: =R7/S7 -> 0.49310187
A11: 20-24 | B11: 110790 | C11: 113067 | D11: =SUM(B11,C11) -> 223857 | F11: 20-24 | G11: 115443 | H11: 114689 | I11: =SUM(G11:H11) -> 230132 | M11: 45-49 | N11: 46 | O11: =S54 -> 76815.482
A12: 25-29 | B12: 99588 | C12: 105074 | D12: =SUM(B12,C12) -> 204662 | F12: 25-29 | G12: 104230 | H12: 106006 | I12: =SUM(G12:H12) -> 210236 | M12: Total | N12: =SUM(N5:N11) -> 55892 | O12: =SUM(O5:O11) -> 735092.97
A13: 30-34 | B13: 86903 | C13: 92787 | D13: =SUM(B13,C13) -> 179690 | F13: 30-34 | G13: 106088 | H13: 110237 | I13: =SUM(G13:H13) -> 216325 | M13: FUENTE: INEGI. Estadísticas de natalidad.
A14: 35-39 | B14: 76375 | C14: 81011 | D14: =SUM(B14,C14) -> 157386 | F14: 35-39 | G14: 103371 | H14: 108399 | I14: =SUM(G14:H14) -> 211770
A15: 40-44 | B15: 63095 | C15: 65856 | D15: =SUM(B15,C15) -> 128951 | F15: 40-44 | G15: 86374 | H15: 91180 | I15: =SUM(G15:H15) -> 177554 | L15: Tasas de crecimiento exponencial para Edades Específicas MEF
A16: 45-49 | B16: 48525 | C16: 50472 | D16: =SUM(B16,C16) -> 98997 | F16: 45-49 | G16: 72906 | H16: 77365 | I16: =SUM(G16:H16) -> 150271 | L16: 15-19
A17: 50-54 | B17: 40702 | C17: 42230 | D17: =SUM(B17,C17) -> 82932 | F17: 50-54 | G17: 60909 | H17: 65052 | I17: =SUM(G17:H17) -> 125961 | L17: Fechas | M17: ti | N17: N | O17: r | Q17: ti | R17: Δt | S17: N27/03/2010
A18: 55-59 | B18: 30959 | C18: 32098 | D18: =SUM(B18,C18) -> 63057 | F18: 55-59 | G18: 46924 | H18: 48197 | I18: =SUM(G18:H18) -> 95121 | L18: 36612 | M18: =2000+7/12+1/365 -> 2000.5861 | N18: =C10 -> 111640 | O18: =LN(N19/N18)/M20 -> 0.014692357 | Q18: =2010+6/12+0/365 -> 2010.5 | R18: =Q18-M18 -> 9.9139269 | S18: =N18*EXP(O18*R18) -> 129145.33
A19: 60-64 | B19: 26017 | C19: 27836 | D19: =SUM(B19,C19) -> 53853 | F19: 60-64 | G19: 37467 | H19: 40060 | I19: =SUM(G19:H19) -> 77527 | L19: 40264 | M19: =2010+7/12+31/365 -> 2010.6683 | N19: =H10 -> 129465
A20: 65-69 | B20: 18870 | C20: 20303 | D20: =SUM(B20,C20) -> 39173 | F20: 65-69 | G20: 26827 | H20: 28840 | I20: =SUM(G20:H20) -> 55667 | L20: Δt | M20: =M19-M18 -> 10.082192
A21: 70-74 | B21: 13890 | C21: 15053 | D21: =SUM(B21,C21) -> 28943 | F21: 70-74 | G21: 20407 | H21: 22425 | I21: =SUM(G21:H21) -> 42832
A22: 75 y más años | B22: 18062 | C22: 21187 | D22: =SUM(B22,C22) -> 39249 | F22: 75-79 | G22: 13197 | H22: 14413 | I22: =SUM(G22:H22) -> 27610 | L22: 20-24
A23: Total | B23: 1140195 | C23: 1157875 | D23: =SUM(B23,C23) -> 2298070 | F23: 80-84 | G23: 7645 | H23: 9431 | I23: =SUM(G23:H23) -> 17076 | L23: Fechas | M23: ti | N23: N | O23: r | Q23: ti | R23: Δt | S23: N27/03/2010
F24: 85 y más años | G24: 5614 | H24: 7618 | I24: =SUM(G24:H24) -> 13232 | L24: =L18 -> 36612 | M24: =M18 -> 2000.5861 | N24: =C11 -> 113067 | O24: =LN(N25/N24)/M26 -> 0.0014127438 | Q24: =Q18 -> 2010.5 | R24: =Q24-M24 -> 9.9139269 | S24: =N24*EXP(O24*R24) -> 114661.74
F25: Total | G25: =SUM(G7:G24) -> 1345179 | H25: =SUM(H7:H24) -> 1365252 | I25: =SUM(I7:I24) -> 2710431 | L25: =L19 -> 40264 | M25: =M19 -> 2010.6683 | N25: =H11 -> 114689
L26: Δt | M26: =M25-M24 -> 10.082192
A28: FUENTE: INEGI. Censo de Población y Vivienda 2010. | L28: 25-29
A29: Consulta de: Población total con estimación Por: Edad Según: Sexo | L29: Fechas | M29: ti | N29: N | O29: r | Q29: ti | R29: Δt | S29: N27/03/2010
L30: =L24 -> 36612 | M30: =M24 -> 2000.5861 | N30: =C12 -> 105074 | O30: =LN(N31/N30)/M32 -> 0.0008758842 | Q30: =Q24 -> 2010.5 | R30: =Q30-M30 -> 9.9139269 | S30: =N30*EXP(O30*R30) -> 105990.38
A31: Tasas de crecimiento exponencial para el Total de la Población | L31: =L25 -> 40264 | M31: =M25 -> 2010.6683 | N31: =H12 -> 106006
A32: 15-19 | L32: Δt | M32: =M31-M30 -> 10.082192
A33: Fechas | B33: ti | C33: N | D33: r | F33: ti | G33: Δt | H33: N27/03/2010
A34: 36612 | B34: =2000+7/12+1/365 -> 2000.5861 | C34: =D23 -> 2298070 | D34: =LN(C35/C34)/B36 -> 0.01636926 | F34: =2010+6/12+0/365 -> 2010.5 | G34: =F34-B34 -> 9.9139269 | H34: =C34*EXP($D$34*G34) -> 2702975.7 | L34: 30-34
A35: 40264 | B35: =2010+7/12+31/365 -> 2010.6683 | C35: =I25 -> 2710431 | L35: Fechas | M35: ti | N35: N | O35: r | Q35: ti | R35: Δt | S35: N27/03/2010
A36: Δt | B36: =B35-B34 -> 10.082192 | L36: =L30 -> 36612 | M36: =M30 -> 2000.5861 | N36: =C13 -> 92787 | O36: =LN(N37/N36)/M38 -> 0.017092122 | Q36: =Q30 -> 2010.5 | R36: =Q36-M36 -> 9.9139269 | S36: =N36*EXP(O36*R36) -> 109920.41
L37: =L31 -> 40264 | M37: =M31 -> 2010.6683 | N37: =H13 -> 110237
L38: Δt | M38: =M37-M36 -> 10.082192
L40: 35-39
L41: Fechas | M41: ti | N41: N | O41: r | Q41: ti | R41: Δt | S41: N27/03/2010
L42: =L36 -> 36612 | M42: =M36 -> 2000.5861 | N42: =C14 -> 81011 | O42: =LN(N43/N42)/M44 -> 0.028885973 | Q42: =Q36 -> 2010.5 | R42: =Q42-M42 -> 9.9139269 | S42: =N42*EXP(O42*R42) -> 107873.41
L43: =L37 -> 40264 | M43: =M37 -> 2010.6683 | N43: =H14 -> 108399
...

Sheet COAHUILA2019
A1: Población total | M1: Coahuila: nacimientos por grupos quinquenales de edad de la madre, 2010
A2: Entidad y municipio : Coahuila de Zaragoza
M4: Edad | N4: Coahuila 2010 | O4: Población 27/03/2010 | Q4: Coahuila: nacimientos por sexo, 2010
A5: Edad | B5: Coahuila 2010 | F5: Edad | G5: Coahuila 2020 | M5: 15-19 | N5: 8185 | O5: =H10 -> 138613
B6: Hombre | C6: Mujer | D6: Total | G6: Hombre | H6: Mujer | I6: Total | M6: 20-24 | N6: 13198 | O6: =H11 -> 136269 | Q6: Hombre | R6: Mujer | S6: Total
A7: 0-4 | B7: 131289 | C7: 126957 | D7: =SUM(B7:C7) -> 258246 | F7: 0-4 | G7: 143940 | H7: 138130 | I7: 282070 | M7: 25-29 | N7: 11718 | O7: =H12 -> 129830 | Q7: 22760 | R7: 21974 | S7: =Q7+R7 -> 44734
A8: 5-9 | B8: 137858 | C8: 132878 | D8: =SUM(B8:C8) -> 270736 | F8: 5-9 | G8: 148702 | H8: 142306 | I8: 291008 | M8: 30-34 | N8: 7294 | O8: =H13 -> 117439 | Q8: FUENTE: INEGI. Estadísticas de natalidad.
A9: 10-14 | B9: 136153 | C9: 132040 | D9: =SUM(B9:C9) -> 268193 | F9: 10-14 | G9: 143169 | H9: 138028 | I9: 281197 | M9: 35-39 | N9: 3306 | O9: =H14 -> 110002
A10: 15-19 | B10: 132477 | C10: 129465 | D10: =SUM(B10:C10) -> 261942 | F10: 15-19 | G10: 143708 | H10: 138613 | I10: 282321 | M10: 40-44 | N10: 739 | O10: =H15 -> 107869 | Q10: K | R10: =R7/S7 -> 0.49121474
A11: 20-24 | B11: 115443 | C11: 114689 | D11: =SUM(B11:C11) -> 230132 | F11: 20-24 | G11: 142846 | H11: 136269 | I11: 279115 | M11: 45-49 | N11: 42 | O11: =H16 -> 101612
A12: 25-29 | B12: 104230 | C12: 106006 | D12: =SUM(B12:C12) -> 210236 | F12: 25-29 | G12: 135859 | H12: 129830 | I12: 265689 | M12: Total | N12: =SUM(N5:N11) -> 44482 | O12: =SUM(O5:O11) -> 841634
A13: 30-34 | B13: 106088 | C13: 110237 | D13: =SUM(B13:C13) -> 216325 | F13: 30-34 | G13: 118554 | H13: 117439 | I13: 235993 | M13: FUENTE: INEGI. Estadísticas de natalidad.
A14: 35-39 | B14: 103371 | C14: 108399 | D14: =SUM(B14:C14) -> 211770 | F14: 35-39 | G14: 102429 | H14: 110002 | I14: 212431
A15: 40-44 | B15: 86374 | C15: 91180 | D15: =SUM(B15:C15) -> 177554 | F15: 40-44 | G15: 97705 | H15: 107869 | I15: 205574 | L15: Tasas de crecimiento exponencial para Edades Específicas MEF
A16: 45-49 | B16: 72906 | C16: 77365 | D16: =SUM(B16:C16) -> 150271 | F16: 45-49 | G16: 94965 | H16: 101612 | I16: 196577 | L16: 15-19
A17: 50-54 | B17: 60909 | C17: 65052 | D17: =SUM(B17:C17) -> 125961 | F17: 50-54 | G17: 82978 | H17: 86508 | I17: 169486 | L17: Fechas | M17: ti | N17: N | O17: r | Q17: ti | R17: Δt | S17: N2019
A18: 55-59 | B18: 46924 | C18: 48197 | D18: =SUM(B18:C18) -> 95121 | F18: 55-59 | G18: 68640 | H18: 71029 | I18: 139669 | L18: 40264 | M18: =2000+7/12+1/365 -> 2000.5861 | N18: =C10 -> 129465 | O18: =LN(N19/N18)/M20 -> 0.0067718711 | Q18: =2010+6/12+0/365 -> 2010.5 | R18: =Q18-M18 -> 9.9139269 | S18: =N18*EXP(O18*R18) -> 138455.14
A19: 60-64 | B19: 37467 | C19: 40060 | D19: =SUM(B19:C19) -> 77527 | F19: 60-64 | G19: 52499 | H19: 54587 | I19: 107086 | L19: 2019 | M19: =2010+7/12+31/365 -> 2010.6683 | N19: =H10 -> 138613
A20: 65-69 | B20: 26827 | C20: 28840 | D20: =SUM(B20:C20) -> 55667 | F20: 65-69 | G20: 37388 | H20: 39619 | I20: 77007 | L20: Δt | M20: =M19-M18 -> 10.082192
A21: 70-74 | B21: 20407 | C21: 22425 | D21: =SUM(B21:C21) -> 42832 | F21: 70-74 | G21: 27306 | H21: 29758 | I21: 57064
A22: 75-79 | B22: 13197 | C22: 14413 | D22: =SUM(B22:C22) -> 27610 | F22: 75-79 | G22: 18326 | H22: 20785 | I22: 39111 | L22: 20-24
A23: 80-84 | B23: 7645 | C23: 9431 | D23: =SUM(B23:C23) -> 17076 | F23: 80-84 | G23: 10678 | H23: 12658 | I23: 23336 | L23: Fechas | M23: ti | N23: N | O23: r | Q23: ti | R23: Δt | S23: N2019
A24: 85 y más años | B24: 5614 | C24: 7618 | D24: =SUM(B24:C24) -> 13232 | F24: 85 y más años | G24: 7809 | H24: 9922 | I24: 17731 | L24: =L18 -> 40264 | M24: =M18 -> 2000.5861 | N24: =C11 -> 114689 | O24: =LN(N25/N24)/M26 -> 0.017100127 | Q24: =Q18 -> 2010.5 | R24: =Q24-M24 -> 9.9139269 | S24: =N24*EXP(O24*R24) -> 135877.47
A25: Total | B25: =SUM(B7:B24) -> 1345179 | C25: =SUM(C7:C24) -> 1365252 | D25: =SUM(D7:D24) -> 2710431 | F25: Total | G25: =SUM(G7:G24) -> 1577501 | H25: =SUM(H7:H24) -> 1584964 | I25: =SUM(I7:I24) -> 3162465 | L25: 2019 | M25: =M19 -> 2010.6683 | N25: =H11 -> 136269
L26: Δt | M26: =M25-M24 -> 10.082192
A28: FUENTE: INEGI. Censo de Población y Vivienda 2010. | L28: 25-29
A29: Consulta de: Población total con estimación Por: Edad Según: Sexo | L29: Fechas | M29: ti | N29: N | O29: r | Q29: ti | R29: Δt | S29: N2019
L30: =L24 -> 40264 | M30: =M24 -> 2000.5861 | N30: =C12 -> 106006 | O30: =LN(N31/N30)/M32 -> 0.020107751 | Q30: =Q24 -> 2010.5 | R30: =Q30-M30 -> 9.9139269 | S30: =N30*EXP(O30*R30) -> 129391.47
A31: Tasas de crecimiento exponencial para el Total de la Población | L31: 2019 | M31: =M25 -> 2010.6683 | N31: =H12 -> 129830
A32: 15-19 | L32: Δt | M32: =M31-M30 -> 10.082192
A33: Fechas | B33: ti | C33: N | D33: r | F33: ti | G33: Δt | H33: N2019
A34: 40264 | B34: =2000+7/12+1/365 -> 2000.5861 | C34: =D25 -> 2710431 | D34: =LN(C35/C34)/B36 -> 0.01529867 | F34: =2010+6/12+0/365 -> 2010.5 | G34: =F34-B34 -> 9.9139269 | H34: =C34*EXP($D$34*G34) -> 3154334.6 | L34: 30-34
A35: 2019 | B35: =2010+7/12+31/365 -> 2010.6683 | C35: =I25 -> 3162465 | L35: Fechas | M35: ti | N35: N | O35: r | Q35: ti | R35: Δt | S35: N2019
A36: Δt | B36: =B35-B34 -> 10.082192 | L36: =L30 -> 40264 | M36: =M30 -> 2000.5861 | N36: =C13 -> 110237 | O36: =LN(N37/N36)/M38 -> 0.0062770534 | Q36: =Q30 -> 2010.5 | R36: =Q36-M36 -> 9.9139269 | S36: =N36*EXP(O36*R36) -> 117315.03
L37: 2019 | M37: =M31 -> 2010.6683 | N37: =H13 -> 117439
L38: Δt | M38: =M37-M36 -> 10.082192
L40: 35-39
L41: Fechas | M41: ti | N41: N | O41: r | Q41: ti | R41: Δt | S41: N2019
L42: =L36 -> 40264 | M42: =M36 -> 2000.5861 | N42: =C14 -> 108399 | O42: =LN(N43/N42)/M44 -> 0.0014560012 | Q42: =Q36 -> 2010.5 | R42: =Q42-M42 -> 9.9139269 | S42: =N42*EXP(O42*R42) -> 109975.05
L43: 2019 | M43: =M37 -> 2010.6683 | N43: =H14 -> 110002
...

Sheet T.MORTALIDAD-F
A1: Coahuila: tabla de mortalidad femenina, 2010
A3: x (edad) | B3: n | C3: nNx | D3: nDx | E3: nmx | F3: nax | G3: nqx | H3: npx | I3: lx | J3: ndx | K3: nLx | L3: Tx
A4: 0 | B4: 1 | C4: 24033 | D4: 247 | E4: =D4/C4 -> 0.010277535 | F4: =IF(E4>=0.107,0.35,0.053+2.8*E4) -> 0.081777098 | G4: =(B4*E4)/(1+(B4-F4)*E4) -> 0.010181452 | H4: =1-G4 -> 0.98981855 | I4: =100000 -> 100000 | J4: =I4-I5 -> 1018.1452 | K4: =(B4*I5)+(F4*J4) -> 99065.116 | L4: =K4+L5 -> 7734608.7 | M4: =L4/I4 -> 77.346087
A5: 1 | B5: 4 | C5: 102924 | D5: 32 | E5: =D5/C5 -> 0.00031090902 | F5: =IF(E4>=0.107,1.361,1.522-1.518*E4) -> 1.5063987 | G5: =(B5*E5)/(1+(B5-F5)*E5) -> 0.0012426727 | H5: =1-G5 -> 0.99875733 | I5: =I4*H4 -> 98981.855 | J5: =I5-I6 -> 123.00204 | K5: =(B5*I6)+(F5*J5) -> 395620.7 | L5: =K5+L6 -> 7635543.6 | M5: =L5/I5 -> 77.140841
A6: 5 | B6: 5 | C6: 132878 | D6: 21 | E6: =D6/C6 -> 0.00015803971 | F6: 2.5 | G6: =(B6*E6)/(1+(B6-F6)*E6) -> 0.00078988644 | H6: =1-G6 -> 0.99921011 | I6: =I5*H5 -> 98858.853 | J6: =I6-I7 -> 78.087268 | K6: =(B6*I7)+(F6*J6) -> 494099.05 | L6: =K6+L7 -> 7239922.9 | M6: =L6/I6 -> 73.234947
A7: 10 | B7: 5 | C7: 132040 | D7: 40 | E7: =D7/C7 -> 0.0003029385 | F7: 2.5 | G7: =(B7*E7)/(1+(B7-F7)*E7) -> 0.0015135462 | H7: =1-G7 -> 0.99848645 | I7: =I6*H6 -> 98780.765 | J7: =I7-I8 -> 149.50926 | K7: =(B7*I8)+(F7*J7) -> 493530.05 | L7: =K7+L8 -> 6745823.8 | M7: =L7/I7 -> 68.290864
A8: 15 | B8: 5 | C8: 129465 | D8: 56 | E8: =D8/C8 -> 0.00043254934 | F8: 2.5 | G8: =(B8*E8)/(1+(B8-F8)*E8) -> 0.0021604105 | H8: =1-G8 -> 0.99783959 | I8: =I7*H7 -> 98631.256 | J8: =I8-I9 -> 213.084 | K8: =(B8*I9)+(F8*J8) -> 492623.57 | L8: =K8+L9 -> 6252293.8 | M8: =L8/I8 -> 63.390592
A9: 20 | B9: 5 | C9: 114689 | D9: 51 | E9: =D9/C9 -> 0.00044468083 | F9: 2.5 | G9: =(B9*E9)/(1+(B9-F9)*E9) -> 0.0022209351 | H9: =1-G9 -> 0.99777906 | I9: =I8*H8 -> 98418.172 | J9: =I9-I10 -> 218.58038 | K9: =(B9*I10)+(F9*J9) -> 491544.41 | L9: =K9+L10 -> 5759670.2 | M9: =L9/I9 -> 58.522426
A10: 25 | B10: 5 | C10: 106006 | D10: 67 | E10: =D10/C10 -> 0.0006320397 | F10: 2.5 | G10: =(B10*E10)/(1+(B10-F10)*E10) -> 0.0031552129 | H10: =1-G10 -> 0.99684479 | I10: =I9*H9 -> 98199.592 | J10: =I10-I11 -> 309.84062 | K10: =(B10*I11)+(F10*J10) -> 490223.36 | L10: =K10+L11 -> 5268125.8 | M10: =L10/I10 -> 53.647125
A11: 30 | B11: 5 | C11: 110237 | D11: 90 | E11: =D11/C11 -> 0.0008164228 | F11: 2.5 | G11: =(B11*E11)/(1+(B11-F11)*E11) -> 0.0040737991 | H11: =1-G11 -> 0.9959262 | I11: =I10*H10 -> 97889.751 | J11: =I11-I12 -> 398.78318 | K11: =(B11*I12)+(F11*J11) -> 488451.8 | L11: =K11+L12 -> 4777902.4 | M11: =L11/I11 -> 48.809016
A12: 35 | B12: 5 | C12: 108399 | D12: 118 | E12: =D12/C12 -> 0.0010885709 | F12: 2.5 | G12: =(B12*E12)/(1+(B12-F12)*E12) -> 0.0054280825 | H12: =1-G12 -> 0.99457192 | I12: =I11*H11 -> 97490.968 | J12: =I12-I13 -> 529.18902 | K12: =(B12*I13)+(F12*J12) -> 486131.87 | L12: =K12+L13 -> 4289450.6 | M12: =L12/I12 -> 43.998441
A13: 40 | B13: 5 | C13: 91180 | D13: 141 | E13: =D13/C13 -> 0.0015463918 | F13: 2.5 | G13: =(B13*E13)/(1+(B13-F13)*E13) -> 0.0077021823 | H13: =1-G13 -> 0.99229782 | I13: =I12*H12 -> 96961.779 | J13: =I13-I14 -> 746.8173 | K13: =(B13*I14)+(F13*J13) -> 482941.85 | L13: =K13+L14 -> 3803318.8 | M13: =L13/I13 -> 39.224928
A14: 45 | B14: 5 | C14: 77365 | D14: 234 | E14: =D14/C14 -> 0.0030246235 | F14: 2.5 | G14: =(B14*E14)/(1+(B14-F14)*E14) -> 0.015009622 | H14: =1-G14 -> 0.98499038 | I14: =I13*H13 -> 96214.962 | J14: =I14-I15 -> 1444.1502 | K14: =(B14*I15)+(F14*J14) -> 477464.43 | L14: =K14+L15 -> 3320376.9 | M14: =L14/I14 -> 34.509985
A15: 50 | B15: 5 | C15: 65052 | D15: 308 | E15: =D15/C15 -> 0.0047346738 | F15: 2.5 | G15: =(B15*E15)/(1+(B15-F15)*E15) -> 0.023396433 | H15: =1-G15 -> 0.97660357 | I15: =I14*H14 -> 94770.812 | J15: =I15-I16 -> 2217.2989 | K15: =(B15*I16)+(F15*J15) -> 468310.81 | L15: =K15+L16 -> 2842912.5 | M15: =L15/I15 -> 29.997764
A16: 55 | B16: 5 | C16: 48197 | D16: 418 | E16: =D16/C16 -> 0.008672739 | F16: 2.5 | G16: =(B16*E16)/(1+(B16-F16)*E16) -> 0.042443443 | H16: =1-G16 -> 0.95755656 | I16: =I15*H15 -> 92553.513 | J16: =I16-I17 -> 3928.2897 | K16: =(B16*I17)+(F16*J16) -> 452946.84 | L16: =K16+L17 -> 2374601.7 | M16: =L16/I16 -> 25.656527
A17: 60 | B17: 5 | C17: 40060 | D17: 509 | E17: =D17/C17 -> 0.012705941 | F17: 2.5 | G17: =(B17*E17)/(1+(B17-F17)*E17) -> 0.061573822 | H17: =1-G17 -> 0.93842618 | I17: =I16*H16 -> 88625.223 | J17: =I17-I18 -> 5456.9937 | K17: =(B17*I18)+(F17*J17) -> 429483.63 | L17: =K17+L18 -> 1921654.8 | M17: =L17/I17 -> 21.682934
... A21: 80 | B21: 5 | C21: 9431 | D21: 694 | E21: =D21/C21 -> 0.073587106 | F21: 2.5 | G21: =(B21*E21)/(1+(B21-F21)*E21) -> 0.31076482 | H21: =1-G21 -> 0.68923518 | I21: =I20*H20 -> 52440.438 | J21: =I21-I22 -> 16296.643 | K21: =(B21*I22)+(F21*J21) -> 221460.58 | L21: =K21+L22 -> 449582.73 | M21: =L21/I21 -> 8.5732069
A22: 85+ | C22: 7618 | D22: 1207 | E22: =D22/C22 -> 0.15844054 | G22: 1 | H22: =1-G22 -> 0 | I22: =I21*H21 -> 36143.795 | J22: =I22-I23 -> 36143.795 | K22: =I22/E22 -> 228122.14 | L22: =K22 -> 228122.14 | M22: =L22/I22 -> 6.3115162
A28: Coahuila: tabla de mortalidad femenina, 2019
A30: x (edad) | B30: n | C30: nNx | D30: nDx | E30: nmx | F30: nax | G30: nqx | H30: npx | I30: lx | J30: ndx | K30: nLx | L30: Tx
A31: 0 | B31: 1 | C31: 27146 | D31: 282 | E31: =D31/C31 -> 0.010388271 | F31: =IF(E31>=0.107,0.35,0.053+2.8*E31) -> 0.082087158 | G31: =(B31*E31)/(1+(B31-F31)*E31) -> 0.010290149 | H31: =1-G31 -> 0.98970985 | I31: =100000 -> 100000 | J31: =I31-I32 -> 1029.0149 | K31: =(B31*I32)+(F31*J31) -> 99055.454 | L31: =K31+L32 -> 7729658.6 | M31: =L31/I31 -> 77.296586
A32: 1 | B32: 4 | C32: 110984 | D32: 50 | E32: =D32/C32 -> 0.00045051539 | F32: =IF(E31>=0.107,1.361,1.522-1.518*E31) -> 1.5062306 | G32: =(B32*E32)/(1+(B32-F32)*E32) -> 0.0018000392 | H32: =1-G32 -> 0.99819996 | I32: =I31*H31 -> 98970.985 | J32: =I32-I33 -> 178.15166 | K32: =(B32*I33)+(F32*J32) -> 395439.67 | L32: =K32+L33 -> 7630603.2 | M32: =L32/I32 -> 77.099396
A33: 5 | B33: 5 | C33: 142306 | D33: 30 | E33: =D33/C33 -> 0.00021081332 | F33: 2.5 | G33: =(B33*E33)/(1+(B33-F33)*E33) -> 0.0010535114 | H33: =1-G33 -> 0.99894649 | I33: =I32*H32 -> 98792.833 | J33: =I33-I34 -> 104.07937 | K33: =(B33*I34)+(F33*J33) -> 493703.97 | L33: =K33+L34 -> 7235163.5 | M33: =L33/I33 -> 73.235712
A34: 10 | B34: 5 | C34: 138028 | D34: 26 | E34: =D34/C34 -> 0.00018836758 | F34: 2.5 | G34: =(B34*E34)/(1+(B34-F34)*E34) -> 0.00094139457 | H34: =1-G34 -> 0.99905861 | I34: =I33*H33 -> 98688.754 | J34: =I34-I35 -> 92.905057 | K34: =(B34*I35)+(F34*J34) -> 493211.51 | L34: =K34+L35 -> 6741459.5 | M34: =L34/I34 -> 68.310312
A35: 15 | B35: 5 | C35: 138613 | D35: 56 | E35: =D35/C35 -> 0.00040400251 | F35: 2.5 | G35: =(B35*E35)/(1+(B35-F35)*E35) -> 0.0020179744 | H35: =1-G35 -> 0.99798203 | I35: =I34*H34 -> 98595.849 | J35: =I35-I36 -> 198.9639 | K35: =(B35*I36)+(F35*J35) -> 492481.84 | L35: =K35+L36 -> 6248248 | M35: =L35/I35 -> 63.372323
A36: 20 | B36: 5 | C36: 136269 | D36: 64 | E36: =D36/C36 -> 0.00046965928 | F36: 2.5 | G36: =(B36*E36)/(1+(B36-F36)*E36) -> 0.0023455424 | H36: =1-G36 -> 0.99765446 | I36: =I35*H35 -> 98396.885 | J36: =I36-I37 -> 230.79406 | K36: =(B36*I37)+(F36*J36) -> 491407.44 | L36: =K36+L37 -> 5755766.2 | M36: =L36/I36 -> 58.495411
A37: 25 | B37: 5 | C37: 129830 | D37: 79 | E37: =D37/C37 -> 0.00060848802 | F37: 2.5 | G37: =(B37*E37)/(1+(B37-F37)*E37) -> 0.0030378189 | H37: =1-G37 -> 0.99696218 | I37: =I36*H36 -> 98166.091 | J37: =I37-I38 -> 298.21081 | K37: =(B37*I38)+(F37*J37) -> 490084.93 | L37: =K37+L38 -> 5264358.8 | M37: =L37/I37 -> 53.627059
A38: 30 | B38: 5 | C38: 117439 | D38: 94 | E38: =D38/C38 -> 0.00080041553 | F38: 2.5 | G38: =(B38*E38)/(1+(B38-F38)*E38) -> 0.0039940854 | H38: =1-G38 -> 0.99600591 | I38: =I37*H37 -> 97867.88 | J38: =I38-I39 -> 390.89267 | K38: =(B38*I39)+(F38*J38) -> 488362.17 | L38: =K38+L39 -> 4774273.8 | M38: =L38/I38 -> 48.782847
A39: 35 | B39: 5 | C39: 110002 | D39: 134 | E39: =D39/C39 -> 0.0012181597 | F39: 2.5 | G39: =(B39*E39)/(1+(B39-F39)*E39) -> 0.0060723058 | H39: =1-G39 -> 0.99392769 | I39: =I38*H38 -> 97476.988 | J39: =I39-I40 -> 591.91007 | K39: =(B39*I40)+(F39*J39) -> 485905.16 | L39: =K39+L40 -> 4285911.7 | M39: =L39/I39 -> 43.968446
A40: 40 | B40: 5 | C40: 107869 | D40: 185 | E40: =D40/C40 -> 0.0017150432 | F40: 2.5 | G40: =(B40*E40)/(1+(B40-F40)*E40) -> 0.008538606 | H40: =1-G40 -> 0.99146139 | I40: =I39*H39 -> 96885.078 | J40: =I40-I41 -> 827.26351 | K40: =(B40*I41)+(F40*J40) -> 482357.23 | L40: =K40+L41 -> 3800006.5 | M40: =L40/I40 -> 39.221793
A41: 45 | B41: 5 | C41: 101612 | D41: 341 | E41: =D41/C41 -> 0.0033559028 | F41: 2.5 | G41: =(B41*E41)/(1+(B41-F41)*E41) -> 0.016639909 | H41: =1-G41 -> 0.98336009 | I41: =I40*H40 -> 96057.814 | J41: =I41-I42 -> 1598.3933 | K41: =(B41*I42)+(F41*J41) -> 476293.09 | L41: =K41+L42 -> 3317649.3 | M41: =L41/I41 -> 34.538047
A42: 50 | B42: 5 | C42: 86508 | D42: 435 | E42: =D42/C42 -> 0.0050284367 | F42: 2.5 | G42: =(B42*E42)/(1+(B42-F42)*E42) -> 0.024830043 | H42: =1-G42 -> 0.97516996 | I42: =I41*H41 -> 94459.421 | J42: =I42-I43 -> 2345.4314 | K42: =(B42*I43)+(F42*J42) -> 466433.52 | L42: =K42+L43 -> 2841356.2 | M42: =L42/I42 -> 30.080178
A43: 55 | B43: 5 | C43: 71029 | D43: 558 | E43: =D43/C43 -> 0.0078559462 | F43: 2.5 | G43: =(B43*E43)/(1+(B43-F43)*E43) -> 0.038523142 | H43: =1-G43 -> 0.96147686 | I43: =I42*H42 -> 92113.989 | J43: =I43-I44 -> 3548.5202 | K43: =(B43*I44)+(F43*J43) -> 451698.65 | L43: =K43+L44 -> 2374922.7 | M43: =L43/I43 -> 25.782432
A44: 60 | B44: 5 | C44: 54587 | D44: 704 | E44: =D44/C44 -> 0.012896844 | F44: 2.5 | G44: =(B44*E44)/(1+(B44-F44)*E44) -> 0.062470052 | H44: =1-G44 -> 0.93752995 | I44: =I43*H43 -> 88565.469 | J44: =I44-I45 -> 5532.6894 | K44: =(B44*I45)+(F44*J44) -> 428995.62 | L44: =K44+L45 -> 1923224 | M44: =L44/I44 -> 21.715281
... A48: 80 | B48: 5 | C48: 12658 | D48: 877 | E48: =D48/C48 -> 0.069284247 | F48: 2.5 | G48: =(B48*E48)/(1+(B48-F48)*E48) -> 0.29527625 | H48: =1-G48 -> 0.70472375 | I48: =I47*H47 -> 51484.303 | J48: =I48-I49 -> 15202.092 | K48: =(B48*I49)+(F48*J48) -> 219416.29 | L48: =K48+L49 -> 457821.65 | M48: =L48/I48 -> 8.8924511
A49: 85+ | C49: 9922 | D49: 1510 | E49: =D49/C49 -> 0.15218706 | G49: 1 | H49: =1-G49 -> 0 | I49: =I48*H48 -> 36282.211 | J49: =I49-I50 -> 36282.211 | K49: =I49/E49 -> 238405.36 | L49: =K49 -> 238405.36 | M49: =L49/I49 -> 6.5708609

Sheet Cuadros a, b, c
A1: AÑO 2010
A2: a. Tasas brutas de natalidad
A3: Tasas brutas de natalidad (b)
A4: Estado | B4: Bz | C4: N 27-03-z | D4: b
A5: Coahuila | B5: =COAHUILA2010!$S$7 -> 56972 | C5: =COAHUILA2010!$H$34 -> 2702975.7 | D5: =B5/C5*1000 -> 21.077511
A7: b. PMEF
A8: Proporción de Mujeres en Edad Fértil
A9: País | B9: MEF 27-03-z | C9: N 27-03-z | D9: PMEF
A10: Coahuila | B10: =COAHUILA2010!$O$12 -> 735092.97 | C10: =COAHUILA2010!$H$34 -> 2702975.7 | D10: =B10/C10 -> 0.27195693
A12: c. TFG
A13: TFG
A14: País | B14: Bz | C14: MEF 27-03-z | D14: TFG | H14: TFG
A15: Coahuila | B15: =B5 -> 56972 | C15: =B10 -> 735092.97 | D15: =B15/C15*1000 -> 77.503121 | H15: =D5/D10 -> 77.503121
A18: AÑO 2019
A19: a. Tasas brutas de natalidad
A20: Tasas brutas de natalidad (b)
A21: Estado | B21: Bz | C21: N 27-03-z | D21: b
A22: Coahuila | B22: =COAHUILA2019!$S$7 -> 44734 | C22: =COAHUILA2019!$H$34 -> 3154334.6 | D22: =B22/C22*1000 -> 14.181755
A24: b. PMEF
A25: Proporción de Mujeres en Edad Fértil
A26: País | B26: MEF 27-03-z | C26: N 27-03-z | D26: PMEF
A27: Coahuila | B27: =COAHUILA2019!$O$12 -> 841634 | C27: =COAHUILA2010!$H$34 -> 2702975.7 | D27: =B27/C27 -> 0.31137312
A29: c. TFG
A30: TFG
A31: País | B31: Bz | C31: MEF 27-03-z | D31: TFG
A32: Coahuila | B32: =B22 -> 44734 | C32: =B27 -> 841634 | D32: =B32/C32*1000 -> 53.15137

Sheet TGF, TBR y TNR
A1: Coahuila 2010 | I1: K | J1: =100/205 -> 0.48780488
A3: Edad | B3: Punto medio | C3: x | D3: x+n | E3: Nacimientos | F3: Población femenina 27/03/2010 | G3: f(x,5) | H3: % f(x,5) | I3: f(x,5) fem | J3: L(x) fem | K3: m+2,5P0 | L3: m+2,5P0 * f(x,5)fem | U3: Análisis de evolución de la fecundidad en Coahuila, 2010–2019 Entre 2010 y 2019, Coahuila muestra una **disminución clara de la fecundidad** en prácticamente todos los grupos de edad reproductiva. La **Tasa Global de Fecundidad (TGF)** pasó de **2.47 hijos por mujer en 2010** a **1.73 hijos por mujer en 2019**, lo que representa una reducción aproximada de **30%**. Esto indica que, en promedio, las mujeres tuvieron menos hijos en 2019 que en 2010. La caída también se observa en la **Tasa Bruta de Reproducción (TBR)**, que bajó de **1.2028** a **0.8429**, y en la **Tasa Neta de Reproducción (TNR)**, que disminuyó de **1.18** a **0.83**. Este cambio es importante porque en 2010 la TNR era mayor que 1, lo que indicaba que la generación de mujeres podía reemplazarse a sí misma. En cambio, para 2019 la TNR es menor que 1, lo que sugiere una fecundidad por debajo del nivel de reemplazo. Por grupos de edad, la fecundidad más alta se mantiene en las mujeres de **20 a 24 años**, aunque también presenta una reducción importante: pasó de **0.1420 en 2010** a **0.0969 en 2019**. El grupo de **25 a 29 años** continúa siendo el segundo más importante, bajando de **0.1312** a **0.0903**. Esto muestra que la mayor concentración de nacimientos sigue ocurriendo entre los **20 y 29 años**, pero con niveles menores que en 2010. También destaca la reducción de la fecundidad adolescente. En el grupo de **15 a 19 años**, la tasa pasó de **0.0922** a **0.0590**, lo cual representa una disminución considerable. Esto puede interpretarse como una menor intensidad de nacimientos en edades tempranas. Aunque la fecundidad disminuye en todos los grupos, la distribución relativa cambia ligeramente. En 2019, los grupos de **30 a 34** y **35 a 39 años** tienen una participación relativamente mayor que en 2010. Esto sugiere un posible **desplazamiento de la fecundidad hacia edades más avanzadas**, es decir, las mujeres tienden a postergar la maternidad. En términos generales, la evolución muestra que Coahuila pasó de un patrón de fecundidad más alto en 2010 a uno más bajo en 2019. La estructura por edad conserva la misma forma: una fecundidad baja al inicio, un máximo entre los 20 y 29 años, y una disminución progresiva después de los 30 años. Sin embargo, toda la curva de 2019 se encuentra por debajo de la de 2010, confirmando una reducción generalizada de la fecundidad en el estado.
A4: 15-19 | B4: 17.5 | C4: 15 | D4: 19 | E4: =COAHUILA2010!$N$5 -> 11909 | F4: =COAHUILA2010!O5 -> 129145.33 | G4: =E4/F4 -> 0.092213942 | H4: =G4/$G$11 -> 0.18699029 | I4: =G4*$J$1 -> 0.04498241 | J4: ='T.MORTALIDAD-F'!K8 -> 492623.57 | K4: =J4/(5*100000) -> 0.98524714 | L4: =K4*I4 -> 0.044318791
A5: 20-24 | B5: 22.5 | C5: 20 | D5: 24 | E5: =COAHUILA2010!N6 -> 16286 | F5: =COAHUILA2010!O6 -> 114661.74 | G5: =E5/F5 -> 0.14203517 | H5: =G5/$G$11 -> 0.28801716 | I5: =G5*$J$1 -> 0.06928545 | J5: ='T.MORTALIDAD-F'!K9 -> 491544.41 | K5: =J5/(5*100000) -> 0.98308882 | L5: =K5*I5 -> 0.068113751
A6: 25-29 | B6: 27.5 | C6: 25 | D6: 29 | E6: =COAHUILA2010!N7 -> 13908 | F6: =COAHUILA2010!O7 -> 105990.38 | G6: =E6/F6 -> 0.13121946 | H6: =G6/$G$11 -> 0.26608519 | I6: =G6*$J$1 -> 0.064009492 | J6: ='T.MORTALIDAD-F'!K10 -> 490223.36 | K6: =J6/(5*100000) -> 0.98044672 | L6: =K6*I6 -> 0.062757896
A7: 30-34 | B7: 32.5 | C7: 30 | D7: 34 | E7: =COAHUILA2010!N8 -> 9223 | F7: =COAHUILA2010!O8 -> 109920.41 | G7: =E7/F7 -> 0.083906162 | H7: =G7/$G$11 -> 0.17014387 | I7: =G7*$J$1 -> 0.040929835 | J7: ='T.MORTALIDAD-F'!K11 -> 488451.8 | K7: =J7/(5*100000) -> 0.9769036 | L7: =K7*I7 -> 0.039984503
A8: 35-39 | B8: 37.5 | C8: 35 | D8: 39 | E8: =COAHUILA2010!N9 -> 3795 | F8: =COAHUILA2010!O9 -> 107873.41 | G8: =E8/F8 -> 0.035180126 | H8: =G8/$G$11 -> 0.071337823 | I8: =G8*$J$1 -> 0.017161037 | J8: ='T.MORTALIDAD-F'!K12 -> 486131.87 | K8: =J8/(5*100000) -> 0.97226374 | L8: =K8*I8 -> 0.016685054
A9: 40-44 | B9: 42.5 | C9: 40 | D9: 44 | E9: =COAHUILA2010!N10 -> 725 | F9: =COAHUILA2010!O10 -> 90686.224 | G9: =E9/F9 -> 0.0079945991 | H9: =G9/$G$11 -> 0.016211349 | I9: =G9*$J$1 -> 0.0038998044 | J9: ='T.MORTALIDAD-F'!K13 -> 482941.85 | K9: =J9/(5*100000) -> 0.9658837 | L9: =K9*I9 -> 0.0037667575
A10: 45-49 | B10: 47.5 | C10: 45 | D10: 49 | E10: =COAHUILA2010!N11 -> 46 | F10: =COAHUILA2010!O11 -> 76815.482 | G10: =E10/F10 -> 0.00059883761 | H10: =G10/$G$11 -> 0.0012143155 | I10: =G10*$J$1 -> 0.00029211591 | J10: ='T.MORTALIDAD-F'!K14 -> 477464.43 | K10: =J10/(5*100000) -> 0.95492887 | L10: =K10*I10 -> 0.00027894991
A11: Total | G11: =SUM(G4:G10) -> 0.4931483 | L11: =SUM(L4:L10) -> 0.2359057
F12: TGF | G12: =SUM(G4:G10)*5 -> 2.4657415
F13: TBR | I13: =G12*J1 -> 1.2028007 | K13: TBR (K obs) | L13: =G12*COAHUILA2010!R10 -> 1.2158617
F14: TNR | L14: =L11*5 -> 1.1795285
A18: Coahuila 2019
A20: Edad | B20: Punto medio | C20: x | D20: x+n | E20: Nacimientos | F20: Población femenina 27/03/2010 | G20: f(x,5) | H20: % f(x,5) | I20: f(x,5) fem | J20: L(x) fem | K20: m+2,5P0 | L20: m+2,5P0 * f(x,5)fem
A21: 15-19 | B21: 17.5 | C21: 15 | D21: 19 | E21: =COAHUILA2019!$N5 -> 8185 | F21: =COAHUILA2019!$O5 -> 138613 | G21: =E21/F21 -> 0.059049296 | H21: =G21/$G$28 -> 0.17086744 | I21: =G21*$J$1 -> 0.028804534 | J21: ='T.MORTALIDAD-F'!K35 -> 492481.84 | K21: =J21/(5*100000) -> 0.98496367 | L21: =K21*I21 -> 0.02837142
A22: 20-24 | B22: 22.5 | C22: 20 | D22: 24 | E22: =COAHUILA2019!$N6 -> 13198 | F22: =COAHUILA2019!$O6 -> 136269 | G22: =E22/F22 -> 0.096852549 | H22: =G22/$G$28 -> 0.28025647 | I22: =G22*$J$1 -> 0.047245146 | J22: ='T.MORTALIDAD-F'!K36 -> 491407.44 | K22: =J22/(5*100000) -> 0.98281488 | L22: =K22*I22 -> 0.046433232
A23: 25-29 | B23: 27.5 | C23: 25 | D23: 29 | E23: =COAHUILA2019!$N7 -> 11718 | F23: =COAHUILA2019!$O7 -> 129830 | G23: =E23/F23 -> 0.090256489 | H23: =G23/$G$28 -> 0.26116985 | I23: =G23*$J$1 -> 0.044027556 | J23: ='T.MORTALIDAD-F'!K37 -> 490084.93 | K23: =J23/(5*100000) -> 0.98016986 | L23: =K23*I23 -> 0.043154483
A24: 30-34 | B24: 32.5 | C24: 30 | D24: 34 | E24: =COAHUILA2019!$N8 -> 7294 | F24: =COAHUILA2019!$O8 -> 117439 | G24: =E24/F24 -> 0.062108839 | H24: =G24/$G$28 -> 0.17972066 | I24: =G24*$J$1 -> 0.030296995 | J24: ='T.MORTALIDAD-F'!K38 -> 488362.17 | K24: =J24/(5*100000) -> 0.97672434 | L24: =K24*I24 -> 0.029591812
A25: 35-39 | B25: 37.5 | C25: 35 | D25: 39 | E25: =COAHUILA2019!$N9 -> 3306 | F25: =COAHUILA2019!$O9 -> 110002 | G25: =E25/F25 -> 0.030053999 | H25: =G25/$G$28 -> 0.086965474 | I25: =G25*$J$1 -> 0.014660487 | J25: ='T.MORTALIDAD-F'!K39 -> 485905.16 | K25: =J25/(5*100000) -> 0.97181033 | L25: =K25*I25 -> 0.014247213
A26: 40-44 | B26: 42.5 | C26: 40 | D26: 44 | E26: =COAHUILA2019!$N10 -> 739 | F26: =COAHUILA2019!$O10 -> 107869 | G26: =E26/F26 -> 0.0068509025 | H26: =G26/$G$28 -> 0.01982405 | I26: =G26*$J$1 -> 0.0033419037 | J26: ='T.MORTALIDAD-F'!K40 -> 482357.23 | K26: =J26/(5*100000) -> 0.96471446 | L26: =K26*I26 -> 0.0032239828
A27: 45-49 | B27: 47.5 | C27: 45 | D27: 49 | E27: =COAHUILA2019!$N11 -> 42 | F27: =COAHUILA2019!$O11 -> 101612 | G27: =E27/F27 -> 0.00041333701 | H27: =G27/$G$28 -> 0.0011960488 | I27: =G27*$J$1 -> 0.00020162781 | J27: ='T.MORTALIDAD-F'!K41 -> 476293.09 | K27: =J27/(5*100000) -> 0.95258617 | L27: =K27*I27 -> 0.00019206786
A28: Total | G28: =SUM(G21:G27) -> 0.34558541 | L28: =SUM(L21:L27) -> 0.16521421
F29: TGF | G29: =SUM(G21:G27)*5 -> 1.7279271
F30: TBR | I30: =G29*J1 -> 0.84289125 | K30: TBR (K obs) | L30: =G29*COAHUILA2019!R10 -> 0.84878323
F31: TNR | L31: =L28*5 -> 0.82607106
K34: Coahuila 2010 | L34: Coahuila 2019
J35: TBR | K35: 1.1772661 | L35: 0.84289125
J36: TNR | K36: 1.1772661 | L36: 0.82607106
